<?xml version="1.0"?>

<robot name="z1_description" xmlns:xacro="http://www.ros.org/wiki/xacro">

    <xacro:include filename="../xacro/z1/const.xacro"/>
    <xacro:include filename="../xacro/z1/gazebo.xacro"/>
    <xacro:include filename="../xacro/z1/transmission.xacro"/>

    <!-- <xacro:property name="UnitreeGripper" value="false"/> -->

    <link name="base"/>

    <joint name="base_static_joint" type="fixed">
        <origin rpy="0 0 0" xyz="0 0 0"/>
        <parent link="base"/>
        <child link="link00"/>
    </joint>

    <link name="link00">
        <visual>
            <origin rpy="0 0 0" xyz="0 0 0"/>
            <geometry>
                <mesh filename="../meshes/z1/z1_Link00.dae" scale="1 1 1"/>
            </geometry>
        </visual>
        <!-- <collision>
            <geometry>
                <cylinder length="0.051" radius="0.0325"/>
            </geometry>
            <origin rpy="0 0 0" xyz="0 0 0.0255"/>
        </collision> -->
        <inertial>
            <origin rpy="0 0 0" xyz="-0.00334984 -0.00013615 0.02495843"/>
            <mass value="0.47247481"/>
            <inertia
                ixx="0.00037937" ixy="0.00000035" ixz="0.00001037"
                iyy="0.00041521" iyz="0.00000099"
                izz="0.00053066"/>
        </inertial>
    </link>

    <joint name="joint1" type="revolute">
        <origin rpy="0 0 0" xyz="0 0 0.0585"/>
        <parent link="link00"/>
        <child link="link01"/>
        <axis xyz="0 0 1"/>
        <dynamics damping="0" friction="0"/>
        <limit effort="30.0" velocity="10" lower="-2.618" upper="2.618"/>
    </joint>

    <link name="link01">
        <visual>
            <origin rpy="0 0 0" xyz="0 0 0"/>
            <geometry>
                <mesh filename="../meshes/z1/z1_Link01.dae" scale="1 1 1"/>
            </geometry>
        </visual>
        <!-- <collision>
            <geometry>
                <cylinder length="0.102" radius="0.0325"/>
            </geometry>
            <origin rpy="0 0 0" xyz="0 0 0"/>
        </collision> -->
        <inertial>
            <origin rpy="0 0 0" xyz="0.00000247 -0.00025198 0.02317169"/>
            <mass value="0.67332551"/>
            <inertia
                ixx="0.00128328" ixy="0.00000006" ixz="0.00000040"
                iyy="0.00071931" iyz="-0.00000050"
                izz="0.00083936"/>
        </inertial>
    </link>

    <joint name="joint2" type="revolute">
        <origin rpy="0 0 0" xyz="0 0 0.045"/>
        <parent link="link01"/>
        <child link="link02"/>
        <axis xyz="0 1 0"/>
        <dynamics damping="0" friction="0"/>
        <limit effort="60.0" velocity="10" lower="0.0" upper="3.14"/>
    </joint>

    <link name="link02">
        <visual>
            <origin rpy="0 0 0" xyz="0 0 0"/>
            <geometry>
                <mesh filename="../meshes/z1/z1_Link02.dae" scale="1 1 1"/>
            </geometry>
        </visual>
        <collision>
            <geometry>
                <cylinder length="0.102" radius="0.0325"/>
            </geometry>
            <origin rpy="1.57 0 0" xyz="0 0 0"/>
        </collision>
        <collision>
            <geometry>
                <cylinder length="0.235" radius="0.0225"/>
            </geometry>
            <origin rpy="0 1.57 0" xyz="-0.1625 0 0"/>
        </collision>
        <collision>
            <geometry>
                <cylinder length="0.051" radius="0.0325"/>
            </geometry>
            <origin rpy="1.57 0 0" xyz="-0.35 0 0"/>
        </collision>
        <inertial>
            <origin rpy="0 0 0" xyz="-0.11012601 0.00240029 0.00158266"/>
            <mass value="1.19132258"/>
            <inertia
                ixx="0.00102138" ixy="-0.00062358" ixz="-0.00000513"
                iyy="0.02429457" iyz="0.00000210"
                izz="0.02466114"/>
        </inertial>
    </link>

    <joint name="joint3" type="revolute">
        <origin rpy="0 0 0" xyz="-0.35 0 0"/>
        <parent link="link02"/>
        <child link="link03"/>
        <axis xyz="0 1 0"/>
        <dynamics damping="0" friction="0"/>
        <limit effort="30.0" velocity="10" lower="-4.78" upper="0.0"/>
    </joint>

    <link name="link03">
        <visual>
            <origin rpy="0 0 0" xyz="0 0 0"/>
            <geometry>
                <mesh filename="../meshes/z1/z1_Link03.dae" scale="1 1 1"/>
            </geometry>
        </visual>
        <collision>
            <geometry>
                <cylinder length="0.116" radius="0.02"/>
            </geometry>
            <origin rpy="0 1.57 0" xyz="0.128 0 0.055"/>
        </collision>
        <collision>
            <geometry>
                <cylinder length="0.059" radius="0.0325"/>
            </geometry>
            <origin rpy="0 1.57 0" xyz="0.2205 0 0.055"/>
        </collision>
        <inertial>
            <origin rpy="0 0 0" xyz="0.10609208 -0.00541815 0.03476383"/>
            <mass value="0.83940874"/>
            <inertia
                ixx="0.00108061" ixy="0.00008669" ixz="0.00208102"
                iyy="0.00954238" iyz="0.00001332"
                izz="0.00886621"/>
        </inertial>
    </link>

    <joint name="joint4" type="revolute">
        <origin rpy="0 0 0" xyz="0.218 0 0.057"/>
        <parent link="link03"/>
        <child link="link04"/>
        <axis xyz="0 1 0"/>
        <dynamics damping="0" friction="0"/>
        <limit effort="30.0" velocity="10" lower="-1.744" upper="1.57"/>
    </joint>

    <link name="link04">
        <visual>
            <origin rpy="0 0 0" xyz="0 0 0"/>
            <geometry>
                <mesh filename="../meshes/z1/z1_Link04.dae" scale="1 1 1"/>
            </geometry>
        </visual>
        <!-- <collision>
            <geometry>
                <cylinder length="0.073" radius="0.0325"/>
            </geometry>
            <origin rpy="1.57 0 0" xyz="0.0472 0 0"/>
        </collision> -->
        <inertial>
            <origin rpy="0 0 0" xyz="0.04366681 0.00364738 -0.00170192"/>
            <mass value="0.56404563"/>
            <inertia
                ixx="0.00031576" ixy="-0.00008130" ixz="-0.00004091"
                iyy="0.00092996" iyz="0.00000596"
                izz="0.00097912"/>
        </inertial>
    </link>

    <joint name="joint5" type="revolute">
        <origin rpy="0 0 0" xyz="0.07 0.0 0.0"/>
        <parent link="link04"/>
        <child link="link05"/>
        <axis xyz="0 0 1"/>
        <dynamics damping="0" friction="0"/>
        <limit effort="30.0" velocity="10" lower="-1.727" upper="1.727"/>
    </joint>

    <link name="link05">
        <visual>
            <origin rpy="0 0 0" xyz="0 0 0"/>
            <geometry>
                <mesh filename="../meshes/z1/z1_Link05.dae" scale="1 1 1"/>
            </geometry>
        </visual>
        <inertial>
            <origin rpy="0 0 0" xyz="0.03121533 0.0 0.00646316"/>
            <mass value="0.38938492"/>
            <inertia
                ixx="0.00017605" ixy="-0.00000040" ixz="-0.00005689"
                iyy="0.00055896" iyz="0.00000013"
                izz="0.00053860"/>
        </inertial>
    </link>

    <joint name="joint6" type="revolute">
        <origin rpy="0 0 0" xyz="0.0492 0.0 0.0"/>
        <parent link="link05"/>
        <child link="link06"/>
        <axis xyz="1 0 0"/>
        <dynamics damping="0" friction="0"/>
        <limit effort="30.0" velocity="10" lower="-2.79" upper="2.79"/>
    </joint>

    <link name="link06">
        <visual>
            <origin rpy="0 0 0" xyz="0 0 0"/>
            <geometry>
                <mesh filename="../meshes/z1/z1_Link06.dae" scale="1 1 1"/>
            </geometry>
        </visual>
        <collision>
            <geometry>
                <cylinder length="0.051" radius="0.0325"/>
            </geometry>
            <origin rpy="0 1.57 0" xyz="0.0255 0 0"/>
        </collision>
        <inertial>
            <origin rpy="0 0 0" xyz="0.02415690 -0.00017355 -0.00143876"/>
            <mass value="0.28875807"/>
            <inertia
                ixx="0.00018328" ixy="-0.00000122" ixz="-0.00000054"
                iyy="0.00014750" iyz="-0.00000008"
                izz="0.00014680"/>
        </inertial>
    </link>

        <joint name="gripperStator" type="fixed">
            <origin rpy="0 0 0" xyz="0.051 0.0 0.0"/>
            <parent link="link06"/>
            <child link="gripperStator"/>
        </joint>

        <link name="gripperStator">
            <visual>
                <origin rpy="0 0 0" xyz="0 0 0"/>
                <geometry>
                    <mesh filename="../meshes/z1/z1_GripperStator.dae" scale="1 1 1"/>
                </geometry>
            </visual>
            <!-- <collision>
                <geometry>
                    <cylinder length="0.051" radius="0.0325"/>
                </geometry>
                <origin rpy="0 0 0" xyz="0 0 0"/>
            </collision> -->
            <!-- <collision>
                <origin rpy="0 0 0" xyz="0 0 0"/>
                <geometry>
                    <mesh filename="../meshes/z1/z1_GripperStator.dae" scale="1 1 1"/>
                </geometry>
            </collision> -->

            <inertial>
                <origin rpy="0 0 0" xyz="0.04764427 -0.00035819 -0.00249162"/>
                <mass value="0.52603655"/>
                <inertia
                    ixx="0.00038683" ixy="0.00000359" ixz="-0.00007662"
                    iyy="0.00068614" iyz="-0.00000209"
                    izz="0.00066293"/>
            </inertial>
        </link>

        <joint name="jointGripper" type="revolute">
            <origin rpy="0 0 0" xyz="0.049 0.0 0"/>
            <parent link="gripperStator"/>
            <child link="gripperMover"/>
            <axis xyz="0 1 0"/>
            <dynamics damping="0" friction="0"/>
            <limit effort="30.0" velocity="10" lower="-1.57" upper="0.0"/>
        </joint>

        <link name="gripperMover">
            <visual>
                <origin rpy="0 0 0" xyz="0 0 0"/>
                <geometry>
                    <mesh filename="../meshes/z1/z1_GripperMover.dae" scale="1 1 1"/>
                </geometry>
            </visual>
            <collision>
                <origin rpy="0 0 0" xyz="0 0 0"/>
                <geometry>
                    <mesh filename="../meshes/z1/z1_GripperMover.dae" scale="1 1 1"/>
                </geometry>
            </collision>
            <inertial>
                <origin rpy="0 0 0" xyz="0.01320633 0.00476708 0.00380534"/>
                <mass value="0.27621302"/>
                <inertia
                    ixx="0.00017716" ixy="-0.00001683" ixz="0.00001786"
                    iyy="0.00026787" iyz="-0.00000262"
                    izz="0.00035728"/>
            </inertial>
        </link>

        <!-- <xacro:motorTransmission name="Gripper"/>

        <gazebo reference="gripperStator">
            <self_collide>true</self_collide>
        </gazebo>

        <gazebo reference="gripperMover">
            <self_collide>true</self_collide>
        </gazebo>

    <xacro:motorTransmission name="1"/>
    <xacro:motorTransmission name="2"/>
    <xacro:motorTransmission name="3"/>
    <xacro:motorTransmission name="4"/>
    <xacro:motorTransmission name="5"/>
    <xacro:motorTransmission name="6"/> -->

</robot>
